Workbook

Sheet General Ledger Detail
A1: General Ledger Detail
A2: Luke Hawkins Coaching Pty Ltd ATF Luke Hawkins Family Trust
A3: For the period 1 July 2025 to 30 June 2026
A5: Date | B5: Source | C5: Description | D5: Reference | E5: Debit | F5: Credit | G5: Running Balance | H5: GST | I5: GST Rate | J5: GST Rate Name
A7: Contractors - Coaches
A8: 46121 | B8: Spend Money | C8: Faith is my Middle Name - Bonus for NTT Live event | D8: 315 | E8: 500 | F8: 0 | G8: =((G7 + E8) - F8) | H8: 0 | I8: 0 | J8: GST Free Expenses
A9: 46007 | B9: Spend Money | C9: Faith is my Middle Name - Christmas Bonus | E9: 600 | F9: 0 | G9: =((G8 + E9) - F9) | H9: 0 | I9: 0 | J9: GST Free Expenses
A10: 46034 | B10: Spend Money | C10: Faith is my Middle Name - One on One Coaching fee - DEcember 2025 | D10: Due Date: 9 Jan 2026 | E10: 5932.76 | F10: 0 | G10: =((G9 + E10) - F10) | H10: 0 | I10: 0 | J10: GST Free Expenses
A11: 45841 | B11: Spend Money | C11: Faith is my Middle Name - One on One Coaching fee - June 2025 | D11: 0097 | E11: 3575.16 | F11: 0 | G11: =((G10 + E11) - F11) | H11: 0 | I11: 0 | J11: GST Free Expenses
A12: 45931 | B12: Spend Money | C12: Faith is my Middle Name - One on One Coaching fee - September 2025 | D12: INV-0100 | E12: 5246.7 | F12: 0 | G12: =((G11 + E12) - F12) | H12: 0 | I12: 0 | J12: GST Free Expenses
A13: 45902 | B13: Payable Invoice | C13: Faith is my Middle Name - One on One Coaching fee for August '25 | D13: INV-0099 | E13: 5649.96 | F13: 0 | G13: =((G12 + E13) - F13) | H13: 0 | I13: 0 | J13: BAS Excluded
A14: 46088 | B14: Payable Invoice | C14: Faith is my Middle Name - One on One Coaching fee for February 2026 | D14: INV-0107 | E14: 6884.76 | F14: 0 | G14: =((G13 + E14) - F14) | H14: 0 | I14: 0 | J14: GST Free Expenses
A15: 45870 | B15: Payable Invoice | C15: Faith is my Middle Name - One on One Coaching fee for July '25 | D15: INV-0098 | E15: 7080.77 | F15: 0 | G15: =((G14 + E15) - F15) | H15: 0 | I15: 0 | J15: BAS Excluded
A16: 46115 | B16: Spend Money | C16: Faith is my Middle Name - One on One Coaching fee for March 2026 | D16: 315 | E16: 9322.4 | F16: 0 | G16: =((G15 + E16) - F16) | H16: 0 | I16: 0 | J16: GST Free Expenses
A17: 45996 | B17: Payable Invoice | C17: Faith is my Middle Name - One on One Coaching fee for November '25 | D17: INV-0102 | E17: 10283.56 | F17: 0 | G17: =((G16 + E17) - F17) | H17: 0 | I17: 0 | J17: GST Free Expenses
A18: 45965 | B18: Payable Invoice | C18: Faith is my Middle Name - One on One Coaching fee for October '25 | D18: INV-0101 | E18: 8473.63 | F18: 0 | G18: =((G17 + E18) - F18) | H18: 0 | I18: 0 | J18: GST Free Expenses
A19: 46059 | B19: Spend Money | C19: Faith is my Middle Name - One on One Coaching fee for the month of January 2026 | D19: INV-0106 | E19: 8460.72 | F19: 0 | G19: =((G18 + E19) - F19) | H19: 0 | I19: 0 | J19: GST Free Expenses
A20: 46154 | B20: Spend Money | C20: No Title Productions Pty Ltd - In house coaching | D20: INV-LH0006 | E20: 901.7 | F20: 0 | G20: =((G19 + E20) - F20) | H20: 90.17 | I20: 10 | J20: GST on Expenses
A21: 46129 | B21: Spend Money | C21: Sheree Murray - for the month of March 2026 | E21: 60 | F21: 0 | G21: =((G20 + E21) - F21) | H21: 0 | I21: 0 | J21: GST Free Expenses
A22: 45839 | B22: Spend Money | C22: Ty Brazel - One on One Coaching | D22: 315 | E22: 3090 | F22: 0 | G22: =(E22 - F22) | H22: 0 | I22: 0 | J22: BAS Excluded
A23: Total Contractors - Coaches | E23: =SUM(E8:E22) | F23: =SUM(F8:F22) | G23: =G22 | H23: =SUM(H8:H22)
A24: Net movement | E24: 76062.12 | F24: 0 | G24: 0 | H24: 0
A26: Contractors - Content Creation
A27: 46007 | B27: Spend Money | C27: Ace Sevilla - Christmas Bonus | D27: 315 | E27: 150 | F27: 0 | G27: =((G26 + E27) - F27) | H27: 0 | I27: 0 | J27: GST Free Expenses
A28: 46083 | B28: Spend Money | C28: Ace Sevilla - Contractor's Fee (video editor) | D28: 315 | E28: 922.22 | F28: 0 | G28: =((G27 + E28) - F28) | H28: 0 | I28: 0 | J28: GST Free Expenses
A29: 46112 | B29: Spend Money | C29: Ace Sevilla - Contractor's Fee (video editor) - March 2026 | D29: 315 | E29: 1021.94 | F29: 0 | G29: =((G28 + E29) - F29) | H29: 0 | I29: 0 | J29: GST Free Expenses
A30: 46143 | B30: Payable Invoice | C30: Ace Sevilla - Contractor's Fee (video editor) for April 2026 | D30: inv 30 | E30: 913.76 | F30: 0 | G30: =((G29 + E30) - F30) | H30: 0 | I30: 0 | J30: GST Free Expenses
A31: 45901 | B31: Payable Invoice | C31: Ace Sevilla - Contractor's Fee (video editor) for August 2025 | D31: inv 24 | E31: 930.42 | F31: 0 | G31: =((G30 + E31) - F31) | H31: 0 | I31: 0 | J31: GST Free Expenses
A32: 46024 | B32: Payable Invoice | C32: Ace Sevilla - Contractor's Fee (video editor) for December 2025 | D32: inv 29 | E32: 1003.55 | F32: 0 | G32: =((G31 + E32) - F32) | H32: 0 | I32: 0 | J32: GST Free Expenses
A33: 46055 | B33: Spend Money | C33: Ace Sevilla - Contractor's Fee (video editor) for January 2026 | D33: 315 | E33: 1003.55 | F33: 0 | G33: =((G32 + E33) - F33) | H33: 0 | I33: 0 | J33: GST Free Expenses
A34: 45839 | B34: Payable Invoice | C34: Ace Sevilla - Contractor's Fee (video editor) for June 2025 | D34: inv 22 | E34: 892.04 | F34: 0 | G34: =(E34 - F34) | H34: 0 | I34: 0 | J34: GST Free Expenses
A35: 45992 | B35: Payable Invoice | C35: Ace Sevilla - Contractor's Fee (video editor) for November 2025 | D35: inv 27 | E35: 1097.58 | F35: 0 | G35: =((G34 + E35) - F35) | H35: 0 | I35: 0 | J35: GST Free Expenses
A36: 45960 | B36: Payable Invoice | C36: Ace Sevilla - Contractor's Fee (video editor) for October 2025 | D36: inv 26 | E36: 618.08 | F36: 0 | G36: =((G35 + E36) - F36) | H36: 0 | I36: 0 | J36: GST Free Expenses
A37: 45931 | B37: Payable Invoice | C37: Ace Sevilla - Contractor's Fee (video editor) for September 2025 | D37: inv 25 | E37: 1097.58 | F37: 0 | G37: =((G36 + E37) - F37) | H37: 0 | I37: 0 | J37: GST Free Expenses
A38: 45846 | B38: Spend Money | C38: Bikash Pandey - Video Editing Service fee | D38: 315 | E38: 1011.52 | F38: 0 | G38: =((G37 + E38) - F38) | H38: 0 | I38: 0 | J38: GST Free Expenses
A39: 45968 | B39: Spend Money | C39: Bikash Pandey - Video Editing Service fee | D39: 315 | E39: 148.23 | F39: 0 | G39: =((G38 + E39) - F39) | H39: 0 | I39: 0 | J39: GST Free Expenses
A40: 45874 | B40: Spend Money | C40: Bikash Pandey - Video Editing Service fee | D40: 315 | E40: 124.28 | F40: 0 | G40: =((G39 + E40) - F40) | H40: 0 | I40: 0 | J40: GST Free Expenses
A41: 45901 | B41: Payable Invoice | C41: Bikash Pandey - Video Editing Service fee for August 2025 | D41: inv023 | E41: 642.21 | F41: 0 | G41: =((G40 + E41) - F41) | H41: 0 | I41: 0 | J41: GST Free Expenses
A42: 46007 | B42: Spend Money | C42: Brock Morgan - Christmas bonus | E42: 300 | F42: 0 | G42: =((G41 + E42) - F42) | H42: 0 | I42: 0 | J42: GST Free Expenses
A43: 46007 | B43: Spend Money | C43: Mamit Chaudhary - Christmas Bonus | E43: 50 | F43: 0 | G43: =((G42 + E43) - F43) | H43: 0 | I43: 0 | J43: BAS Excluded
...

Sheet Summary
A1: What do they do | B1: Name | C1: Fees | D1: Entity | E1: Risk | F1: ABN | G1: Check if valid | H1: Status: Active or offboarded | I1: Australian resident or overseas | J1: Do they perform more than 30 hours a week for you? | K1: Do you have a contract in place? | L1: Payment: Do you pay them directly or a labour hire firm. | M1: Control: Does your business have legal right to control how, where an when the worker does their work | N1: Integration: the worker serves in your business. They are contractually required to perform work as a representative of your business. | O1: Mode of remuneration: are they paid either for their time worked, a price per item or activity or commission or are they paid for a fixed fe or for a specific result. | P1: Is there a clause in the contract where it does not allow them to delegate or subcontract their work. | Q1: Does your business provide the equipment for them to do the work or do they have their own and you reimburse them for the expenses incurred. | R1: Risk: Workers bear little to no risk, your business bears the commercial risk for any cost arising out of injury of defect for work. | S1: Generation of goodwill. Your business benefits from any goodwill arising from the work of the worker.
A2: Coach | B2: Faith is My Middle Name | C2: =SUM('General Ledger Detail'!E8:E19) | D2: Individual | E2: Yes | H2: Active | I2: australian resident | J2: less | K2: yes | L2: directly | M2: no | O2: hourly for coaching and commissions for sales and item based for events
A3: Content | B3: Ace Sevilla | C3: =SUM('General Ledger Detail'!E27:E37) | D3: Individual | E3: Yes | H3: Active | I3: overseas | J3: less | K3: yes | L3: directly | M3: no | N3: no | O3: hourly | P3: no | S3: yes
A4: Content | B4: Bickash Pandey | C4: =+SUM('General Ledger Detail'!E38:E41) | D4: Individual | E4: Yes | H4: off boarded | I4: overseas | J4: less | K4: yes | L4: directly | M4: no | N4: no | O4: hourly | P4: no | S4: yes
A5: Content | B5: Brock Morgan | C5: =+'General Ledger Detail'!E42 | D5: Individual | E5: Yes | H5: Active | I5: australian resident | J5: less | K5: yes | L5: directly | M5: no | N5: yes | O5: hourly | P5: yes | S5: yes
A6: Content | B6: Mamit Chaudhary | C6: =SUM('General Ledger Detail'!E43:E50) | D6: Individual | E6: Yes | H6: Active | I6: overseas | J6: less | K6: yes | L6: directly | M6: no | N6: no | O6: hourly | P6: no | S6: yes
A7: Content | B7: Thapa Anashrut | C7: =SUM('General Ledger Detail'!E51:E105) | D7: Individual | E7: Yes | H7: Active | I7: overseas | J7: less | K7: no | L7: directly | M7: no | O7: hourly
A8: Virtual asssistant | B8: Upwork (Nawal) | C8: =SUM('General Ledger Detail'!E106:E134) | D8: Individual | E8: Yes | H8: Active | I8: overseas | J8: less | K8: no | L8: directly | M8: no | O8: hourly
A9: Operations | B9: Dan Diaz Guerrero | C9: =SUM('General Ledger Detail'!E139:E169) | D9: Individual | E9: Yes | H9: Active | I9: overseas | J9: more | K9: yes | L9: directly | M9: no | N9: yes | O9: hourly + commisions | P9: no | S9: yes
A10: Sales | B10: Fernando Diaz Guerrero | C10: =SUM('General Ledger Detail'!E176:E181) | D10: Individual | E10: Yes | H10: Active | I10: overseas | J10: less | K10: no | L10: directly | M10: no | O10: hourly + commisions
A11: Sales | B11: Gabriela Fuchs | C11: =SUM('General Ledger Detail'!E182:E186) | D11: Individual | E11: Yes | H11: off boarded | I11: resided in australia and in venezuela and canada | J11: less | K11: no | L11: directly | M11: no | O11: hourly + commisions
A12: Sales | B12: Hilal Husseyin | C12: =SUM('General Ledger Detail'!E187:E192) | D12: Individual | E12: Yes | H12: off boarded | I12: overseas | J12: less | K12: yes | L12: directly | M12: no | N12: yes | P12: no | S12: yes
A13: Sales | B13: Lisa Cooke | C13: =SUM('General Ledger Detail'!E193:E197) | D13: Individual | E13: Yes | H13: Active | I13: overseas | J13: less | K13: no | L13: directly | M13: no
A14: Sales | B14: Sarah Mcneil | C14: =SUM('General Ledger Detail'!E198:E207) | D14: Individual | E14: Yes | H14: Active | I14: australian resident | J14: less | K14: yes | L14: directly | M14: no | N14: yes | P14: no | S14: yes
A15: Sales | B15: Sarika Narkhede | C15: =SUM('General Ledger Detail'!E208:E216) | D15: Individual | E15: Yes | H15: Active | I15: australian resident | J15: less | K15: no | L15: directly | M15: no
A16: Virtual Assistant | B16: Charmine Longakit | C16: =SUM('General Ledger Detail'!E221:E237) | D16: Individual | E16: Yes | H16: off boarded | I16: overseas | J16: less | K16: no | L16: directly | M16: no
A17: Virtual Assistant | B17: Kate L. Angulo | C17: =SUM('General Ledger Detail'!E238:E260) | D17: Individual | E17: Yes | H17: Active | I17: overseas | J17: more | K17: no | L17: directly | M17: no
A18: Virtual Assistant | B18: Lorie Jane L. Rojo | C18: =SUM('General Ledger Detail'!E261:E273) | D18: Individual | E18: Yes | H18: Active | I18: overseas | J18: less | K18: no | L18: directly | M18: no
A19: Virtual Assistant | B19: Sunshine Lorilla | C19: =SUM('General Ledger Detail'!E277:E288) | D19: Individual | E19: Yes | H19: Active | I19: overseas | J19: less | K19: no | L19: directly | M19: no
A20: Virtual Assistant | B20: Upwork (Nawal) | C20: =SUM('General Ledger Detail'!E289:E298) | D20: Individual | E20: Yes | H20: Active | I20: overseas | J20: less | K20: no | L20: directly | M20: no
A21: Virtual Assistant | B21: Blessing | D21: Individual | E21: Yes | H21: Active | I21: overseas | J21: less | K21: no | L21: upwork- labour hire firm | M21: no
C22: =SUM(C2:C20)
